[2024-11-04T16:20:02.911+0000] {taskinstance.py:1157} INFO - Dependencies all met for dep_context=non-requeueable deps ti=<TaskInstance: etl_game_pipeline.steam_load manual__2024-11-04T16:14:59.946494+00:00 [queued]>
[2024-11-04T16:20:02.919+0000] {taskinstance.py:1157} INFO - Dependencies all met for dep_context=requeueable deps ti=<TaskInstance: etl_game_pipeline.steam_load manual__2024-11-04T16:14:59.946494+00:00 [queued]>
[2024-11-04T16:20:02.920+0000] {taskinstance.py:1359} INFO - Starting attempt 2 of 2
[2024-11-04T16:20:02.934+0000] {taskinstance.py:1380} INFO - Executing <Task(PythonOperator): steam_load> on 2024-11-04 16:14:59.946494+00:00
[2024-11-04T16:20:02.938+0000] {standard_task_runner.py:57} INFO - Started process 93 to run task
[2024-11-04T16:20:02.941+0000] {standard_task_runner.py:84} INFO - Running: ['airflow', 'tasks', 'run', 'etl_game_pipeline', 'steam_load', 'manual__2024-11-04T16:14:59.946494+00:00', '--job-id', '30', '--raw', '--subdir', 'DAGS_FOLDER/steam_dag.py', '--cfg-path', '/tmp/tmps9u8ilzv']
[2024-11-04T16:20:02.944+0000] {standard_task_runner.py:85} INFO - Job 30: Subtask steam_load
[2024-11-04T16:20:02.987+0000] {task_command.py:415} INFO - Running <TaskInstance: etl_game_pipeline.steam_load manual__2024-11-04T16:14:59.946494+00:00 [running]> on host f6d6761c5673
[2024-11-04T16:20:03.188+0000] {taskinstance.py:1660} INFO - Exporting env vars: AIRFLOW_CTX_DAG_OWNER='Jordan Welborn' AIRFLOW_CTX_DAG_ID='etl_game_pipeline' AIRFLOW_CTX_TASK_ID='steam_load' AIRFLOW_CTX_EXECUTION_DATE='2024-11-04T16:14:59.946494+00:00' AIRFLOW_CTX_TRY_NUMBER='2' AIRFLOW_CTX_DAG_RUN_ID='manual__2024-11-04T16:14:59.946494+00:00'
[2024-11-04T16:20:03.189+0000] {logging_mixin.py:151} INFO - Current Working Directory: /opt/airflow
[2024-11-04T16:20:03.194+0000] {taskinstance.py:1935} ERROR - Task failed with exception
Traceback (most recent call last):
  File "/home/airflow/.local/lib/python3.9/site-packages/airflow/operators/python.py", line 192, in execute
    return_value = self.execute_callable()
  File "/home/airflow/.local/lib/python3.9/site-packages/airflow/operators/python.py", line 209, in execute_callable
    return self.python_callable(*self.op_args, **self.op_kwargs)
  File "/opt/airflow/pipelines/game_pipeline.py", line 55, in load_data
    games_df = pd.read_csv(game_path)
  File "/home/airflow/.local/lib/python3.9/site-packages/pandas/io/parsers/readers.py", line 948, in read_csv
    return _read(filepath_or_buffer, kwds)
  File "/home/airflow/.local/lib/python3.9/site-packages/pandas/io/parsers/readers.py", line 611, in _read
    parser = TextFileReader(filepath_or_buffer, **kwds)
  File "/home/airflow/.local/lib/python3.9/site-packages/pandas/io/parsers/readers.py", line 1448, in __init__
    self._engine = self._make_engine(f, self.engine)
  File "/home/airflow/.local/lib/python3.9/site-packages/pandas/io/parsers/readers.py", line 1705, in _make_engine
    self.handles = get_handle(
  File "/home/airflow/.local/lib/python3.9/site-packages/pandas/io/common.py", line 863, in get_handle
    handle = open(
FileNotFoundError: [Errno 2] No such file or directory: '/data/GameData.csv'
[2024-11-04T16:20:03.204+0000] {taskinstance.py:1398} INFO - Marking task as FAILED. dag_id=etl_game_pipeline, task_id=steam_load, execution_date=20241104T161459, start_date=20241104T162002, end_date=20241104T162003
[2024-11-04T16:20:03.214+0000] {standard_task_runner.py:104} ERROR - Failed to execute job 30 for task steam_load ([Errno 2] No such file or directory: '/data/GameData.csv'; 93)
[2024-11-04T16:20:03.234+0000] {local_task_job_runner.py:228} INFO - Task exited with return code 1
[2024-11-04T16:20:03.247+0000] {taskinstance.py:2776} INFO - 0 downstream tasks scheduled from follow-on schedule check
