[2024-11-04T15:46:16.285+0000] {taskinstance.py:1157} INFO - Dependencies all met for dep_context=non-requeueable deps ti=<TaskInstance: etl_game_pipeline.steam_load manual__2024-11-04T15:41:12.930536+00:00 [queued]>
[2024-11-04T15:46:16.293+0000] {taskinstance.py:1157} INFO - Dependencies all met for dep_context=requeueable deps ti=<TaskInstance: etl_game_pipeline.steam_load manual__2024-11-04T15:41:12.930536+00:00 [queued]>
[2024-11-04T15:46:16.293+0000] {taskinstance.py:1359} INFO - Starting attempt 2 of 2
[2024-11-04T15:46:16.306+0000] {taskinstance.py:1380} INFO - Executing <Task(PythonOperator): steam_load> on 2024-11-04 15:41:12.930536+00:00
[2024-11-04T15:46:16.311+0000] {standard_task_runner.py:57} INFO - Started process 66 to run task
[2024-11-04T15:46:16.314+0000] {standard_task_runner.py:84} INFO - Running: ['airflow', 'tasks', 'run', 'etl_game_pipeline', 'steam_load', 'manual__2024-11-04T15:41:12.930536+00:00', '--job-id', '21', '--raw', '--subdir', 'DAGS_FOLDER/steam_dag.py', '--cfg-path', '/tmp/tmp57m5s0y_']
[2024-11-04T15:46:16.318+0000] {standard_task_runner.py:85} INFO - Job 21: Subtask steam_load
[2024-11-04T15:46:16.366+0000] {task_command.py:415} INFO - Running <TaskInstance: etl_game_pipeline.steam_load manual__2024-11-04T15:41:12.930536+00:00 [running]> on host f6d6761c5673
[2024-11-04T15:46:16.569+0000] {taskinstance.py:1660} INFO - Exporting env vars: AIRFLOW_CTX_DAG_OWNER='Jordan Welborn' AIRFLOW_CTX_DAG_ID='etl_game_pipeline' AIRFLOW_CTX_TASK_ID='steam_load' AIRFLOW_CTX_EXECUTION_DATE='2024-11-04T15:41:12.930536+00:00' AIRFLOW_CTX_TRY_NUMBER='2' AIRFLOW_CTX_DAG_RUN_ID='manual__2024-11-04T15:41:12.930536+00:00'
[2024-11-04T15:46:16.572+0000] {taskinstance.py:1935} ERROR - Task failed with exception
Traceback (most recent call last):
  File "/home/airflow/.local/lib/python3.9/site-packages/airflow/operators/python.py", line 192, in execute
    return_value = self.execute_callable()
  File "/home/airflow/.local/lib/python3.9/site-packages/airflow/operators/python.py", line 209, in execute_callable
    return self.python_callable(*self.op_args, **self.op_kwargs)
  File "/opt/airflow/pipelines/game_pipeline.py", line 52, in load_data
    games_df = pd.read_csv(game_path)
  File "/home/airflow/.local/lib/python3.9/site-packages/pandas/io/parsers/readers.py", line 948, in read_csv
    return _read(filepath_or_buffer, kwds)
  File "/home/airflow/.local/lib/python3.9/site-packages/pandas/io/parsers/readers.py", line 611, in _read
    parser = TextFileReader(filepath_or_buffer, **kwds)
  File "/home/airflow/.local/lib/python3.9/site-packages/pandas/io/parsers/readers.py", line 1448, in __init__
    self._engine = self._make_engine(f, self.engine)
  File "/home/airflow/.local/lib/python3.9/site-packages/pandas/io/parsers/readers.py", line 1705, in _make_engine
    self.handles = get_handle(
  File "/home/airflow/.local/lib/python3.9/site-packages/pandas/io/common.py", line 863, in get_handle
    handle = open(
FileNotFoundError: [Errno 2] No such file or directory: '/opt/airflow/data/GameData.csv'
[2024-11-04T15:46:16.582+0000] {taskinstance.py:1398} INFO - Marking task as FAILED. dag_id=etl_game_pipeline, task_id=steam_load, execution_date=20241104T154112, start_date=20241104T154616, end_date=20241104T154616
[2024-11-04T15:46:16.593+0000] {standard_task_runner.py:104} ERROR - Failed to execute job 21 for task steam_load ([Errno 2] No such file or directory: '/opt/airflow/data/GameData.csv'; 66)
[2024-11-04T15:46:16.609+0000] {local_task_job_runner.py:228} INFO - Task exited with return code 1
[2024-11-04T15:46:16.622+0000] {taskinstance.py:2776} INFO - 0 downstream tasks scheduled from follow-on schedule check
